Workbook
Name rangeExpenseCategories: 'Category Setup'!$B$129:$B$168
Name rangeIncomeCategories: 'Category Setup'!$B$175:$B$181
Name rangeTimePeriods: 'Date Info'!$E$12:$E$18

Sheet DashBoard
C3: Your Actual Data of Income
C4: ="Total ("&'Date Info'!$C$26&")" -> Total (1 month)
B5: InHand (Bank) Holding | C5: ='Total & Budget Targets'!E92 -> 5 | D5: =C5/$C$8 -> 0.010121457
B6: Crypto Holdings | C6: 34 | D6: =C6/$C$8 -> 0.068825911
B7: Shares & Commodities Holdings | C7: 455 | D7: =C7/$C$8 -> 0.92105263
B8: Total Wealth Savings | C8: =SUM(C5:C7) -> 494 | D8: =C8/$C$8 -> 1

Sheet Expenses
B2: Expense Data
B5: Date (MM-DD-YYYY) | C5: Month (Ctrl-D) | D5: Store / Vendor | E5: Amount | F5: Expense Category | G5: ExpenseKeys | H5: Notes (Optional)
B6: 45717 | C6: =IF(B6="", "", TEXT(B6, "MMM YY")) -> Mar 25 | D6: Kings Restaurant LLP | E6: 33 | F6: Restaurant & Dining Out | G6: =_xludf.IFNA(VLOOKUP(F6,'Category Setup'!B:D,3,0), "") -> #NAME? | H6: Ice Cream Bring for sis
B7: 45717 | C7: =IF(B7="", "", TEXT(B7, "MMM YY")) -> Mar 25 | D7: Lobh Petrolleum | E7: 5 | F7: Fuel | G7: =_xludf.IFNA(VLOOKUP(F7,'Category Setup'!B:D,3,0), "") -> #NAME? | H7: Mahender Sir Car CNG
C328: =IF(B328="", "", TEXT(B328, "MMM YY")) | G328: =_xludf.IFNA(VLOOKUP(F328,'Category Setup'!B:D,3,0), "") -> #NAME?
C329: =IF(B329="", "", TEXT(B329, "MMM YY")) | G329: =_xludf.IFNA(VLOOKUP(F329,'Category Setup'!B:D,3,0), "") -> #NAME?
C330: =IF(B330="", "", TEXT(B330, "MMM YY")) | G330: =_xludf.IFNA(VLOOKUP(F330,'Category Setup'!B:D,3,0), "") -> #NAME?
C331: =IF(B331="", "", TEXT(B331, "MMM YY")) | G331: =_xludf.IFNA(VLOOKUP(F331,'Category Setup'!B:D,3,0), "") -> #NAME?
C332: =IF(B332="", "", TEXT(B332, "MMM YY")) | G332: =_xludf.IFNA(VLOOKUP(F332,'Category Setup'!B:D,3,0), "") -> #NAME?
C333: =IF(B333="", "", TEXT(B333, "MMM YY")) | G333: =_xludf.IFNA(VLOOKUP(F333,'Category Setup'!B:D,3,0), "") -> #NAME?
C334: =IF(B334="", "", TEXT(B334, "MMM YY")) | G334: =_xludf.IFNA(VLOOKUP(F334,'Category Setup'!B:D,3,0), "") -> #NAME?
C335: =IF(B335="", "", TEXT(B335, "MMM YY")) | G335: =_xludf.IFNA(VLOOKUP(F335,'Category Setup'!B:D,3,0), "") -> #NAME?
C336: =IF(B336="", "", TEXT(B336, "MMM YY")) | G336: =_xludf.IFNA(VLOOKUP(F336,'Category Setup'!B:D,3,0), "") -> #NAME?
C337: =IF(B337="", "", TEXT(B337, "MMM YY")) | G337: =_xludf.IFNA(VLOOKUP(F337,'Category Setup'!B:D,3,0), "") -> #NAME?
C338: =IF(B338="", "", TEXT(B338, "MMM YY")) | G338: =_xludf.IFNA(VLOOKUP(F338,'Category Setup'!B:D,3,0), "") -> #NAME?
C339: =IF(B339="", "", TEXT(B339, "MMM YY")) | G339: =_xludf.IFNA(VLOOKUP(F339,'Category Setup'!B:D,3,0), "") -> #NAME?
... C997: =IF(B997="", "", TEXT(B997, "MMM YY")) | G997: =_xludf.IFNA(VLOOKUP(F997,'Category Setup'!B:D,3,0), "") -> #NAME?

Sheet Income
B2: Income Data
B4: Date (MM-DD-YYYY) | C4: Source | D4: Amount | E4: Income Category | F4: Notes (Optional)
B5: 45717 | C5: Salary | D5: 300 | E5: Job / Salary | F5: Feb Salary

Sheet InHand
B2: InHand Data
B4: Date (MM-DD-YYYY) | C4: Source | D4: Amount | E4: Income Category | F4: Notes (Optional)
B5: 45716 | C5: Personal SBI Account | D5: 5 | E5: Personal SBI (Saving) | F5: All time Saving

Sheet Comparison to Budget Targets
B1: Start of time period (MM-DD-YYYY): | D1: 45717 | E1: <<< Input here
B2: End of time period (MM-DD-YYYY): | D2: 45746 | E2: <<< Input here
B3: Implied # of months | D3: =IF(MONTH(D2)=2,MAX(ROUND((D2-D1+2)/(365/12),1),0),MAX(ROUND((D2-D1+1)/(365/12),1),0)) -> 1
B5: ="Budget Summary: "&TEXT($D$1,"mmmm-dd-yyyy")&" to "&TEXT($D$2,"mmmm-dd-yyyy")&" ("&TEXT($D$3,"#,##0")&IF(ROUND($D$3,0)=1," month"," months")&")" -> Budget Summary: March-01-2025 to March-30-2025 (1 month)
D7: Expenses by Category | G7: Variance to Budget (Your Actuals Minus Your Target)
B8: Expense Categories | D8: Actual Expenses | E8: Budget Target | G8: $ | H8: %
A9: ='Category Setup'!A129 -> 1 | B9: ='Category Setup'!B129 -> Bills & Utilities | D9: =IF($B9="","",SUMIFS(Expenses!$E:$E,Expenses!$F:$F,$B9,Expenses!$B:$B,">="&$D$1,Expenses!$B:$B,"<="&$D$2)) -> 0 | E9: =IF($B9="","",'Total & Budget Targets'!$G4*$D$3) -> 0 | G9: =IF($B9="","",D9-E9) -> 0 | H9: =IF($B9="","",IFERROR(D9/E9,0)) -> 0
A10: ='Category Setup'!A130 -> 2 | B10: ='Category Setup'!B130 -> Childcare & Baby Needs | D10: =IF($B10="","",SUMIFS(Expenses!$E:$E,Expenses!$F:$F,$B10,Expenses!$B:$B,">="&$D$1,Expenses!$B:$B,"<="&$D$2)) -> 0 | E10: =IF($B10="","",'Total & Budget Targets'!$G5*$D$3) -> 0 | G10: =IF($B10="","",D10-E10) -> 0 | H10: =IF($B10="","",IFERROR(D10/E10,0)) -> 0
A11: ='Category Setup'!A131 -> 3 | B11: ='Category Setup'!B131 -> Commute | D11: =IF($B11="","",SUMIFS(Expenses!$E:$E,Expenses!$F:$F,$B11,Expenses!$B:$B,">="&$D$1,Expenses!$B:$B,"<="&$D$2)) -> 0 | E11: =IF($B11="","",'Total & Budget Targets'!$G6*$D$3) -> 0 | G11: =IF($B11="","",D11-E11) -> 0 | H11: =IF($B11="","",IFERROR(D11/E11,0)) -> 0
A12: ='Category Setup'!A132 -> 4 | B12: ='Category Setup'!B132 -> Education | D12: =IF($B12="","",SUMIFS(Expenses!$E:$E,Expenses!$F:$F,$B12,Expenses!$B:$B,">="&$D$1,Expenses!$B:$B,"<="&$D$2)) -> 0 | E12: =IF($B12="","",'Total & Budget Targets'!$G7*$D$3) -> 0 | G12: =IF($B12="","",D12-E12) -> 0 | H12: =IF($B12="","",IFERROR(D12/E12,0)) -> 0
A13: ='Category Setup'!A133 -> 5 | B13: ='Category Setup'!B133 -> Electronics & Gadgets | D13: =IF($B13="","",SUMIFS(Expenses!$E:$E,Expenses!$F:$F,$B13,Expenses!$B:$B,">="&$D$1,Expenses!$B:$B,"<="&$D$2)) -> 0 | E13: =IF($B13="","",'Total & Budget Targets'!$G8*$D$3) -> 0 | G13: =IF($B13="","",D13-E13) -> 0 | H13: =IF($B13="","",IFERROR(D13/E13,0)) -> 0
A14: ='Category Setup'!A134 -> 6 | B14: ='Category Setup'!B134 -> Entertainment | D14: =IF($B14="","",SUMIFS(Expenses!$E:$E,Expenses!$F:$F,$B14,Expenses!$B:$B,">="&$D$1,Expenses!$B:$B,"<="&$D$2)) -> 0 | E14: =IF($B14="","",'Total & Budget Targets'!$G9*$D$3) -> 0 | G14: =IF($B14="","",D14-E14) -> 0 | H14: =IF($B14="","",IFERROR(D14/E14,0)) -> 0
A15: ='Category Setup'!A135 -> 7 | B15: ='Category Setup'!B135 -> Familly | D15: =IF($B15="","",SUMIFS(Expenses!$E:$E,Expenses!$F:$F,$B15,Expenses!$B:$B,">="&$D$1,Expenses!$B:$B,"<="&$D$2)) -> 0 | E15: =IF($B15="","",'Total & Budget Targets'!$G10*$D$3) -> 0 | G15: =IF($B15="","",D15-E15) -> 0 | H15: =IF($B15="","",IFERROR(D15/E15,0)) -> 0
A16: ='Category Setup'!A136 -> 8 | B16: ='Category Setup'!B136 -> Fitness | D16: =IF($B16="","",SUMIFS(Expenses!$E:$E,Expenses!$F:$F,$B16,Expenses!$B:$B,">="&$D$1,Expenses!$B:$B,"<="&$D$2)) -> 0 | E16: =IF($B16="","",'Total & Budget Targets'!$G11*$D$3) -> 0 | G16: =IF($B16="","",D16-E16) -> 0 | H16: =IF($B16="","",IFERROR(D16/E16,0)) -> 0
A17: ='Category Setup'!A137 -> 9 | B17: ='Category Setup'!B137 -> Snacks & Quick Bites | D17: =IF($B17="","",SUMIFS(Expenses!$E:$E,Expenses!$F:$F,$B17,Expenses!$B:$B,">="&$D$1,Expenses!$B:$B,"<="&$D$2)) -> 0 | E17: =IF($B17="","",'Total & Budget Targets'!$G12*$D$3) -> 0 | G17: =IF($B17="","",D17-E17) -> 0 | H17: =IF($B17="","",IFERROR(D17/E17,0)) -> 0
A18: ='Category Setup'!A138 -> 10 | B18: ='Category Setup'!B138 -> Fuel | D18: =IF($B18="","",SUMIFS(Expenses!$E:$E,Expenses!$F:$F,$B18,Expenses!$B:$B,">="&$D$1,Expenses!$B:$B,"<="&$D$2)) -> 5 | E18: =IF($B18="","",'Total & Budget Targets'!$G13*$D$3) -> 0 | G18: =IF($B18="","",D18-E18) -> 5 | H18: =IF($B18="","",IFERROR(D18/E18,0)) -> 0
A19: ='Category Setup'!A139 -> 11 | B19: ='Category Setup'!B139 -> Gifts | D19: =IF($B19="","",SUMIFS(Expenses!$E:$E,Expenses!$F:$F,$B19,Expenses!$B:$B,">="&$D$1,Expenses!$B:$B,"<="&$D$2)) -> 0 | E19: =IF($B19="","",'Total & Budget Targets'!$G14*$D$3) -> 0 | G19: =IF($B19="","",D19-E19) -> 0 | H19: =IF($B19="","",IFERROR(D19/E19,0)) -> 0
A20: ='Category Setup'!A140 -> 12 | B20: ='Category Setup'!B140 -> Groceries | D20: =IF($B20="","",SUMIFS(Expenses!$E:$E,Expenses!$F:$F,$B20,Expenses!$B:$B,">="&$D$1,Expenses!$B:$B,"<="&$D$2)) -> 0 | E20: =IF($B20="","",'Total & Budget Targets'!$G15*$D$3) -> 0 | G20: =IF($B20="","",D20-E20) -> 0 | H20: =IF($B20="","",IFERROR(D20/E20,0)) -> 0
... A48: ='Category Setup'!A168 | B48: ='Category Setup'!B168 | D48: =IF($B48="","",SUMIFS(Expenses!$E:$E,Expenses!$F:$F,$B48,Expenses!$B:$B,">="&$D$1,Expenses!$B:$B,"<="&$D$2)) | E48: =IF($B48="","",'Total & Budget Targets'!$G43*$D$3) | G48: =IF($B48="","",D48-E48) | H48: =IF($B48="","",IFERROR(D48/E48,0))
B49: Total Expenses | D49: =SUM(D9:D48) -> 38 | E49: =SUM(E9:E48) -> 0 | G49: =SUM(G9:G48) -> 38 | H49: =IF($B49="","",IFERROR(D49/E49,0)) -> 0
D51: Income by Category | G51: Variance to Budget
B52: Income Categories | D52: Actual Income | E52: Budget Target | G52: $ | H52: %
A53: ='Category Setup'!A175 -> 1 | B53: ='Category Setup'!B175 -> Expense Money | D53: =IF($B53="","",SUMIFS(Income!$D:$D,Income!$E:$E,$B53,Income!$B:$B,">="&$D$1,Income!$B:$B,"<="&$D$2)) -> 0 | E53: =IF($B53="","",'Total & Budget Targets'!$G48*$D$3) -> 0 | G53: =IF($B53="","",D53-E53) -> 0 | H53: =IF($B53="","",IFERROR(D53/E53,0)) -> 0
A54: ='Category Setup'!A176 -> 2 | B54: ='Category Setup'!B176 -> Job / Salary | D54: =IF($B54="","",SUMIFS(Income!$D:$D,Income!$E:$E,$B54,Income!$B:$B,">="&$D$1,Income!$B:$B,"<="&$D$2)) -> 300 | E54: =IF($B54="","",'Total & Budget Targets'!$G49*$D$3) -> 0 | G54: =IF($B54="","",D54-E54) -> 300 | H54: =IF($B54="","",IFERROR(D54/E54,0)) -> 0
A55: ='Category Setup'!A177 -> 3 | B55: ='Category Setup'!B177 -> Side Income | D55: =IF($B55="","",SUMIFS(Income!$D:$D,Income!$E:$E,$B55,Income!$B:$B,">="&$D$1,Income!$B:$B,"<="&$D$2)) -> 0 | E55: =IF($B55="","",'Total & Budget Targets'!$G50*$D$3) -> 0 | G55: =IF($B55="","",D55-E55) -> 0 | H55: =IF($B55="","",IFERROR(D55/E55,0)) -> 0
A56: ='Category Setup'!A178 | B56: ='Category Setup'!B178 | D56: =IF($B56="","",SUMIFS(Income!$D:$D,Income!$E:$E,$B56,Income!$B:$B,">="&$D$1,Income!$B:$B,"<="&$D$2)) | E56: =IF($B56="","",'Total & Budget Targets'!$G51*$D$3) | G56: =IF($B56="","",D56-E56) | H56: =IF($B56="","",IFERROR(D56/E56,0))
A57: ='Category Setup'!A179 | B57: ='Category Setup'!B179 | D57: =IF($B57="","",SUMIFS(Income!$D:$D,Income!$E:$E,$B57,Income!$B:$B,">="&$D$1,Income!$B:$B,"<="&$D$2)) | E57: =IF($B57="","",'Total & Budget Targets'!$G52*$D$3) | G57: =IF($B57="","",D57-E57) | H57: =IF($B57="","",IFERROR(D57/E57,0))
A58: ='Category Setup'!A180 | B58: ='Category Setup'!B180 | D58: =IF($B58="","",SUMIFS(Income!$D:$D,Income!$E:$E,$B58,Income!$B:$B,">="&$D$1,Income!$B:$B,"<="&$D$2)) | E58: =IF($B58="","",'Total & Budget Targets'!$G53*$D$3) | G58: =IF($B58="","",D58-E58) | H58: =IF($B58="","",IFERROR(D58/E58,0))
A59: ='Category Setup'!A181 | B59: ='Category Setup'!B181 | D59: =IF($B59="","",SUMIFS(Income!$D:$D,Income!$E:$E,$B59,Income!$B:$B,">="&$D$1,Income!$B:$B,"<="&$D$2)) | E59: =IF($B59="","",'Total & Budget Targets'!$G54*$D$3) | G59: =IF($B59="","",D59-E59) | H59: =IF($B59="","",IFERROR(D59/E59,0))
A60: ='Category Setup'!A182 | B60: ='Category Setup'!B182 | D60: =IF($B60="","",SUMIFS(Income!$D:$D,Income!$E:$E,$B60,Income!$B:$B,">="&$D$1,Income!$B:$B,"<="&$D$2)) | E60: =IF($B60="","",'Total & Budget Targets'!$G55*$D$3) | G60: =IF($B60="","",D60-E60) | H60: =IF($B60="","",IFERROR(D60/E60,0))
A61: ='Category Setup'!A183 | B61: ='Category Setup'!B183 | D61: =IF($B61="","",SUMIFS(Income!$D:$D,Income!$E:$E,$B61,Income!$B:$B,">="&$D$1,Income!$B:$B,"<="&$D$2)) | E61: =IF($B61="","",'Total & Budget Targets'!$G56*$D$3) | G61: =IF($B61="","",D61-E61) | H61: =IF($B61="","",IFERROR(D61/E61,0))
A62: ='Category Setup'!A184 | B62: ='Category Setup'!B184 | D62: =IF($B62="","",SUMIFS(Income!$D:$D,Income!$E:$E,$B62,Income!$B:$B,">="&$D$1,Income!$B:$B,"<="&$D$2)) | E62: =IF($B62="","",'Total & Budget Targets'!$G57*$D$3) | G62: =IF($B62="","",D62-E62) | H62: =IF($B62="","",IFERROR(D62/E62,0))
A63: ='Category Setup'!A185 | B63: ='Category Setup'!B185 | D63: =IF($B63="","",SUMIFS(Income!$D:$D,Income!$E:$E,$B63,Income!$B:$B,">="&$D$1,Income!$B:$B,"<="&$D$2)) | E63: =IF($B63="","",'Total & Budget Targets'!$G58*$D$3) | G63: =IF($B63="","",D63-E63) | H63: =IF($B63="","",IFERROR(D63/E63,0))
A64: ='Category Setup'!A186 | B64: ='Category Setup'!B186 | D64: =IF($B64="","",SUMIFS(Income!$D:$D,Income!$E:$E,$B64,Income!$B:$B,">="&$D$1,Income!$B:$B,"<="&$D$2)) | E64: =IF($B64="","",'Total & Budget Targets'!$G59*$D$3) | G64: =IF($B64="","",D64-E64) | H64: =IF($B64="","",IFERROR(D64/E64,0))
... A67: ='Category Setup'!A189 | B67: ='Category Setup'!B189 | D67: =IF($B67="","",SUMIFS(Income!$D:$D,Income!$E:$E,$B67,Income!$B:$B,">="&$D$1,Income!$B:$B,"<="&$D$2)) | E67: =IF($B67="","",'Total & Budget Targets'!$G62*$D$3) | G67: =IF($B67="","",D67-E67) | H67: =IF($B67="","",IFERROR(D67/E67,0))
B68: Total Income | D68: =SUM(D53:D67) -> 300 | E68: =SUM(E53:E67) -> 0 | G68: =SUM(G53:G67) -> 300 | H68: =IF($B68="","",IFERROR(D68/E68,0)) -> 0
D70: Summary | G70: Variance to Budget
D71: Actual | E71: Budget Target | G71: $ | H71: %
B72: Total Income | D72: =D68 -> 300 | E72: =E68 -> 0 | G72: =D72-E72 -> 300 | H72: =IF($B72="","",IFERROR(D72/E72,0)) -> 0
B73: Total Expenses | D73: =D49 -> 38 | E73: =E49 -> 0 | G73: =D73-E73 -> 38 | H73: =IF($B73="","",IFERROR(D73/E73,0)) -> 0
...

Sheet Total & Budget Targets
D2: Your Actual Spending (Based on the data you've entered so far) | G2: Your Budget Target (to be Manually Entered in Column G)
B3: Expense Categories | D3: Monthly Average | E3: ="Total ("&'Date Info'!$C$26&")" -> Total (1 month) | G3: Monthly Spend | H3: Implied Annual Spend
A4: ='Category Setup'!A129 -> 1 | B4: ='Category Setup'!B129 -> Bills & Utilities | D4: =IF($B4="","",E4/'Date Info'!$C$25) -> 0 | E4: =IF($B4="","",SUMIFS(Expenses!$E:$E,Expenses!$F:$F,$B4)) -> 0 | G4: 0 | H4: =IF($B4="","",G4*12) -> 0
A5: ='Category Setup'!A130 -> 2 | B5: ='Category Setup'!B130 -> Childcare & Baby Needs | D5: =IF($B5="","",E5/'Date Info'!$C$25) -> 0 | E5: =IF($B5="","",SUMIFS(Expenses!$E:$E,Expenses!$F:$F,$B5)) -> 0 | G5: 0 | H5: =IF($B5="","",G5*12) -> 0
A6: ='Category Setup'!A131 -> 3 | B6: ='Category Setup'!B131 -> Commute | D6: =IF($B6="","",E6/'Date Info'!$C$25) -> 0 | E6: =IF($B6="","",SUMIFS(Expenses!$E:$E,Expenses!$F:$F,$B6)) -> 0 | G6: 0 | H6: =IF($B6="","",G6*12) -> 0
A7: ='Category Setup'!A132 -> 4 | B7: ='Category Setup'!B132 -> Education | D7: =IF($B7="","",E7/'Date Info'!$C$25) -> 0 | E7: =IF($B7="","",SUMIFS(Expenses!$E:$E,Expenses!$F:$F,$B7)) -> 0 | G7: 0 | H7: =IF($B7="","",G7*12) -> 0
A8: ='Category Setup'!A133 -> 5 | B8: ='Category Setup'!B133 -> Electronics & Gadgets | D8: =IF($B8="","",E8/'Date Info'!$C$25) -> 0 | E8: =IF($B8="","",SUMIFS(Expenses!$E:$E,Expenses!$F:$F,$B8)) -> 0 | G8: 0 | H8: =IF($B8="","",G8*12) -> 0
A9: ='Category Setup'!A134 -> 6 | B9: ='Category Setup'!B134 -> Entertainment | D9: =IF($B9="","",E9/'Date Info'!$C$25) -> 0 | E9: =IF($B9="","",SUMIFS(Expenses!$E:$E,Expenses!$F:$F,$B9)) -> 0 | G9: 0 | H9: =IF($B9="","",G9*12) -> 0
A10: ='Category Setup'!A135 -> 7 | B10: ='Category Setup'!B135 -> Familly | D10: =IF($B10="","",E10/'Date Info'!$C$25) -> 0 | E10: =IF($B10="","",SUMIFS(Expenses!$E:$E,Expenses!$F:$F,$B10)) -> 0 | G10: 0 | H10: =IF($B10="","",G10*12) -> 0
A11: ='Category Setup'!A136 -> 8 | B11: ='Category Setup'!B136 -> Fitness | D11: =IF($B11="","",E11/'Date Info'!$C$25) -> 0 | E11: =IF($B11="","",SUMIFS(Expenses!$E:$E,Expenses!$F:$F,$B11)) -> 0 | G11: 0 | H11: =IF($B11="","",G11*12) -> 0
A12: ='Category Setup'!A137 -> 9 | B12: ='Category Setup'!B137 -> Snacks & Quick Bites | D12: =IF($B12="","",E12/'Date Info'!$C$25) -> 0 | E12: =IF($B12="","",SUMIFS(Expenses!$E:$E,Expenses!$F:$F,$B12)) -> 0 | G12: 0 | H12: =IF($B12="","",G12*12) -> 0
A13: ='Category Setup'!A138 -> 10 | B13: ='Category Setup'!B138 -> Fuel | D13: =IF($B13="","",E13/'Date Info'!$C$25) -> 5 | E13: =IF($B13="","",SUMIFS(Expenses!$E:$E,Expenses!$F:$F,$B13)) -> 5 | G13: 0 | H13: =IF($B13="","",G13*12) -> 0
A14: ='Category Setup'!A139 -> 11 | B14: ='Category Setup'!B139 -> Gifts | D14: =IF($B14="","",E14/'Date Info'!$C$25) -> 0 | E14: =IF($B14="","",SUMIFS(Expenses!$E:$E,Expenses!$F:$F,$B14)) -> 0 | G14: 0 | H14: =IF($B14="","",G14*12) -> 0
A15: ='Category Setup'!A140 -> 12 | B15: ='Category Setup'!B140 -> Groceries | D15: =IF($B15="","",E15/'Date Info'!$C$25) -> 0 | E15: =IF($B15="","",SUMIFS(Expenses!$E:$E,Expenses!$F:$F,$B15)) -> 0 | G15: 0 | H15: =IF($B15="","",G15*12) -> 0
... A30: ='Category Setup'!A155 -> 27 | B30: ='Category Setup'!B155 -> Other | D30: =IF($B30="","",E30/'Date Info'!$C$25) -> 0 | E30: =IF($B30="","",SUMIFS(Expenses!$E:$E,Expenses!$F:$F,$B30)) -> 0 | G30: 0 | H30: =IF($B30="","",G30*12) -> 0
A31: ='Category Setup'!A156 | B31: ='Category Setup'!B156 | D31: =IF($B31="","",E31/'Date Info'!$C$25) | E31: =IF($B31="","",SUMIFS(Expenses!$E:$E,Expenses!$F:$F,$B31)) | H31: =IF($B31="","",G31*12)
A32: ='Category Setup'!A157 | B32: ='Category Setup'!B157 | D32: =IF($B32="","",E32/'Date Info'!$C$25) | E32: =IF($B32="","",SUMIFS(Expenses!$E:$E,Expenses!$F:$F,$B32)) | H32: =IF($B32="","",G32*12)
A33: ='Category Setup'!A158 | B33: ='Category Setup'!B158 | D33: =IF($B33="","",E33/'Date Info'!$C$25) | E33: =IF($B33="","",SUMIFS(Expenses!$E:$E,Expenses!$F:$F,$B33)) | H33: =IF($B33="","",G33*12)
A34: ='Category Setup'!A159 | B34: ='Category Setup'!B159 | D34: =IF($B34="","",E34/'Date Info'!$C$25) | E34: =IF($B34="","",SUMIFS(Expenses!$E:$E,Expenses!$F:$F,$B34)) | H34: =IF($B34="","",G34*12)
A35: ='Category Setup'!A160 | B35: ='Category Setup'!B160 | D35: =IF($B35="","",E35/'Date Info'!$C$25) | E35: =IF($B35="","",SUMIFS(Expenses!$E:$E,Expenses!$F:$F,$B35)) | H35: =IF($B35="","",G35*12)
A36: ='Category Setup'!A161 | B36: ='Category Setup'!B161 | D36: =IF($B36="","",E36/'Date Info'!$C$25) | E36: =IF($B36="","",SUMIFS(Expenses!$E:$E,Expenses!$F:$F,$B36)) | H36: =IF($B36="","",G36*12)
A37: ='Category Setup'!A162 | B37: ='Category Setup'!B162 | D37: =IF($B37="","",E37/'Date Info'!$C$25) | E37: =IF($B37="","",SUMIFS(Expenses!$E:$E,Expenses!$F:$F,$B37)) | H37: =IF($B37="","",G37*12)
A38: ='Category Setup'!A163 | B38: ='Category Setup'!B163 | D38: =IF($B38="","",E38/'Date Info'!$C$25) | E38: =IF($B38="","",SUMIFS(Expenses!$E:$E,Expenses!$F:$F,$B38)) | H38: =IF($B38="","",G38*12)
A39: ='Category Setup'!A164 | B39: ='Category Setup'!B164 | D39: =IF($B39="","",E39/'Date Info'!$C$25) | E39: =IF($B39="","",SUMIFS(Expenses!$E:$E,Expenses!$F:$F,$B39)) | H39: =IF($B39="","",G39*12)
A40: ='Category Setup'!A165 | B40: ='Category Setup'!B165 | D40: =IF($B40="","",E40/'Date Info'!$C$25) | E40: =IF($B40="","",SUMIFS(Expenses!$E:$E,Expenses!$F:$F,$B40)) | H40: =IF($B40="","",G40*12)
A41: ='Category Setup'!A166 | B41: ='Category Setup'!B166 | D41: =IF($B41="","",E41/'Date Info'!$C$25) | E41: =IF($B41="","",SUMIFS(Expenses!$E:$E,Expenses!$F:$F,$B41)) | H41: =IF($B41="","",G41*12)
A42: ='Category Setup'!A167 | B42: ='Category Setup'!B167 | D42: =IF($B42="","",E42/'Date Info'!$C$25) | E42: =IF($B42="","",SUMIFS(Expenses!$E:$E,Expenses!$F:$F,$B42)) | H42: =IF($B42="","",G42*12)
A43: ='Category Setup'!A168 | B43: ='Category Setup'!B168 | D43: =IF($B43="","",E43/'Date Info'!$C$25) | E43: =IF($B43="","",SUMIFS(Expenses!$E:$E,Expenses!$F:$F,$B43)) | H43: =IF($B43="","",G43*12)
B44: Total Expenses | D44: =SUMIFS(D$4:D$43,$A$4:$A$43,">0") -> 38 | E44: =SUMIFS(E$4:E$43,$A$4:$A$43,">0") -> 38 | G44: =SUMIFS(G$4:G$43,$A$4:$A$43,">0") -> 0 | H44: =SUMIFS(H$4:H$43,$A$4:$A$43,">0") -> 0
D46: Your Actual Income | G46: Your Budget Target
B47: Income Categories | D47: Monthly Average | E47: ="Total ("&'Date Info'!$C$26&")" -> Total (1 month) | G47: Monthly Income | H47: Implied Annual Income
A48: ='Category Setup'!A175 -> 1 | B48: ='Category Setup'!B175 -> Expense Money | D48: =IF($B48="","",E48/'Date Info'!$C$25) -> 0 | E48: =IF($B48="","",SUMIFS(Income!$D:$D,Income!$E:$E,$B48)) -> 0 | G48: 0 | H48: =IF($B48="","",G48*12) -> 0
A49: ='Category Setup'!A176 -> 2 | B49: ='Category Setup'!B176 -> Job / Salary | D49: =IF($B49="","",E49/'Date Info'!$C$25) -> 300 | E49: =IF($B49="","",SUMIFS(Income!$D:$D,Income!$E:$E,$B49)) -> 300 | G49: 0 | H49: =IF($B49="","",G49*12) -> 0
A50: ='Category Setup'!A177 -> 3 | B50: ='Category Setup'!B177 -> Side Income | D50: =IF($B50="","",E50/'Date Info'!$C$25) -> 0 | E50: =IF($B50="","",SUMIFS(Income!$D:$D,Income!$E:$E,$B50)) -> 0 | G50: 0 | H50: =IF($B50="","",G50*12) -> 0
A51: ='Category Setup'!A178 | B51: ='Category Setup'!B178 | D51: =IF($B51="","",E51/'Date Info'!$C$25) | E51: =IF($B51="","",SUMIFS(Income!$D:$D,Income!$E:$E,$B51)) | G51: 25000 | H51: =IF($B51="","",G51*12)
A52: ='Category Setup'!A179 | B52: ='Category Setup'!B179 | D52: =IF($B52="","",E52/'Date Info'!$C$25) | E52: =IF($B52="","",SUMIFS(Income!$D:$D,Income!$E:$E,$B52)) | G52: 0 | H52: =IF($B52="","",G52*12)
A53: ='Category Setup'!A180 | B53: ='Category Setup'!B180 | D53: =IF($B53="","",E53/'Date Info'!$C$25) | E53: =IF($B53="","",SUMIFS(Income!$D:$D,Income!$E:$E,$B53)) | G53: 0 | H53: =IF($B53="","",G53*12)
A54: ='Category Setup'!A181 | B54: ='Category Setup'!B181 | D54: =IF($B54="","",E54/'Date Info'!$C$25) | E54: =IF($B54="","",SUMIFS(Income!$D:$D,Income!$E:$E,$B54)) | G54: 0 | H54: =IF($B54="","",G54*12)
A55: ='Category Setup'!A182 | B55: ='Category Setup'!B182 | D55: =IF($B55="","",E55/'Date Info'!$C$25) | E55: =IF($B55="","",SUMIFS(Income!$D:$D,Income!$E:$E,$B55)) | G55: 0 | H55: =IF($B55="","",G55*12)
A56: ='Category Setup'!A183 | B56: ='Category Setup'!B183 | D56: =IF($B56="","",E56/'Date Info'!$C$25) | E56: =IF($B56="","",SUMIFS(Income!$D:$D,Income!$E:$E,$B56)) | H56: =IF($B56="","",G56*12)
...

Sheet Selected Time Period Data
C3: Time Period | E3: Totals | H3: Ratios | J3: Averages - Actuals | M3: Budget Targets
B4: Month | C4: Start Date | D4: End Date | E4: Expenses | F4: Income | G4: Savings | H4: Expense Ratio | I4: Savings Ratio | J4: Expenses | K4: Income | L4: Savings | M4: Expenses | N4: Income | O4: Savings
A5: 1 | C5: 45689 | D5: =EOMONTH(C5,0) -> 45716 | E5: =IF($D5="","",IFERROR(SUMIFS(Expenses!$E:$E,Expenses!$B:$B,">="&$C5,Expenses!$B:$B,"<="&$D5),"na")) -> 0 | F5: =IF($D5="","",IFERROR(SUMIFS(Income!$D:$D,Income!$B:$B,">="&$C5,Income!$B:$B,"<="&$D5),"na")) -> 0 | G5: =IF(E5="","",F5-E5) -> 0 | H5: =IFERROR(E5/F5,"na") -> na | I5: =IFERROR(G5/F5,"na") -> na | J5: =IF(E5="","",SUM(E$5:E$404)/'Date Info'!$E$21) -> 38 | K5: =IF(F5="","",SUM(F$5:F$404)/'Date Info'!$E$21) -> 300 | L5: =IF(G5="","",SUM(G$5:G$404)/'Date Info'!$E$21) -> 262 | M5: =IF($D5="","",'Total & Budget Targets'!$G$44) -> 0 | N5: =IF($D5="","",'Total & Budget Targets'!$G$63) -> 0 | O5: =IF($D5="","",'Total & Budget Targets'!$G$69) -> 0
A6: =A5+1 -> 2 | C6: =IF(D5="","",IF(D5+1>'Date Info'!$D$21,"",D5+1)) -> 45717 | D6: =IFERROR(IF(C6="","",IF(EOMONTH(C6,0)>'Date Info'!$D$21,'Date Info'!$D$21,EOMONTH(C6,0))),"") -> 45747 | E6: =IF($D6="","",IFERROR(SUMIFS(Expenses!$E:$E,Expenses!$B:$B,">="&$C6,Expenses!$B:$B,"<="&$D6),"na")) -> 38 | F6: =IF($D6="","",IFERROR(SUMIFS(Income!$D:$D,Income!$B:$B,">="&$C6,Income!$B:$B,"<="&$D6),"na")) -> 300 | G6: =IF(E6="","",F6-E6) -> 262 | H6: =IFERROR(E6/F6,"na") -> 0.12666667 | I6: =IFERROR(G6/F6,"na") -> 0.87333333 | J6: =IF(E6="","",J$5) -> 38 | K6: =IF(F6="","",K$5) -> 300 | L6: =IF(G6="","",L$5) -> 262 | M6: =IF($D6="","",'Total & Budget Targets'!$G$44) -> 0 | N6: =IF($D6="","",'Total & Budget Targets'!$G$63) -> 0 | O6: =IF($D6="","",'Total & Budget Targets'!$G$69) -> 0
A7: =A6+1 -> 3 | C7: =IF(D6="","",IF(D6+1>'Date Info'!$D$21,"",D6+1)) -> 45748 | D7: =IFERROR(IF(C7="","",IF(EOMONTH(C7,0)>'Date Info'!$D$21,'Date Info'!$D$21,EOMONTH(C7,0))),"") -> 45777 | E7: =IF($D7="","",IFERROR(SUMIFS(Expenses!$E:$E,Expenses!$B:$B,">="&$C7,Expenses!$B:$B,"<="&$D7),"na")) -> 0 | F7: =IF($D7="","",IFERROR(SUMIFS(Income!$D:$D,Income!$B:$B,">="&$C7,Income!$B:$B,"<="&$D7),"na")) -> 0 | G7: =IF(E7="","",F7-E7) -> 0 | H7: =IFERROR(E7/F7,"na") -> na | I7: =IFERROR(G7/F7,"na") -> na | J7: =IF(E7="","",J$5) -> 38 | K7: =IF(F7="","",K$5) -> 300 | L7: =IF(G7="","",L$5) -> 262 | M7: =IF($D7="","",'Total & Budget Targets'!$G$44) -> 0 | N7: =IF($D7="","",'Total & Budget Targets'!$G$63) -> 0 | O7: =IF($D7="","",'Total & Budget Targets'!$G$69) -> 0
A8: =A7+1 -> 4 | C8: =IF(D7="","",IF(D7+1>'Date Info'!$D$21,"",D7+1)) -> 45778 | D8: =IFERROR(IF(C8="","",IF(EOMONTH(C8,0)>'Date Info'!$D$21,'Date Info'!$D$21,EOMONTH(C8,0))),"") -> 45808 | E8: =IF($D8="","",IFERROR(SUMIFS(Expenses!$E:$E,Expenses!$B:$B,">="&$C8,Expenses!$B:$B,"<="&$D8),"na")) -> 0 | F8: =IF($D8="","",IFERROR(SUMIFS(Income!$D:$D,Income!$B:$B,">="&$C8,Income!$B:$B,"<="&$D8),"na")) -> 0 | G8: =IF(E8="","",F8-E8) -> 0 | H8: =IFERROR(E8/F8,"na") -> na | I8: =IFERROR(G8/F8,"na") -> na | J8: =IF(E8="","",J$5) -> 38 | K8: =IF(F8="","",K$5) -> 300 | L8: =IF(G8="","",L$5) -> 262 | M8: =IF($D8="","",'Total & Budget Targets'!$G$44) -> 0 | N8: =IF($D8="","",'Total & Budget Targets'!$G$63) -> 0 | O8: =IF($D8="","",'Total & Budget Targets'!$G$69) -> 0
A9: =A8+1 -> 5 | C9: =IF(D8="","",IF(D8+1>'Date Info'!$D$21,"",D8+1)) -> 45809 | D9: =IFERROR(IF(C9="","",IF(EOMONTH(C9,0)>'Date Info'!$D$21,'Date Info'!$D$21,EOMONTH(C9,0))),"") -> 45838 | E9: =IF($D9="","",IFERROR(SUMIFS(Expenses!$E:$E,Expenses!$B:$B,">="&$C9,Expenses!$B:$B,"<="&$D9),"na")) -> 0 | F9: =IF($D9="","",IFERROR(SUMIFS(Income!$D:$D,Income!$B:$B,">="&$C9,Income!$B:$B,"<="&$D9),"na")) -> 0 | G9: =IF(E9="","",F9-E9) -> 0 | H9: =IFERROR(E9/F9,"na") -> na | I9: =IFERROR(G9/F9,"na") -> na | J9: =IF(E9="","",J$5) -> 38 | K9: =IF(F9="","",K$5) -> 300 | L9: =IF(G9="","",L$5) -> 262 | M9: =IF($D9="","",'Total & Budget Targets'!$G$44) -> 0 | N9: =IF($D9="","",'Total & Budget Targets'!$G$63) -> 0 | O9: =IF($D9="","",'Total & Budget Targets'!$G$69) -> 0
A10: =A9+1 -> 6 | C10: =IF(D9="","",IF(D9+1>'Date Info'!$D$21,"",D9+1)) -> 45839 | D10: =IFERROR(IF(C10="","",IF(EOMONTH(C10,0)>'Date Info'!$D$21,'Date Info'!$D$21,EOMONTH(C10,0))),"") -> 45869 | E10: =IF($D10="","",IFERROR(SUMIFS(Expenses!$E:$E,Expenses!$B:$B,">="&$C10,Expenses!$B:$B,"<="&$D10),"na")) -> 0 | F10: =IF($D10="","",IFERROR(SUMIFS(Income!$D:$D,Income!$B:$B,">="&$C10,Income!$B:$B,"<="&$D10),"na")) -> 0 | G10: =IF(E10="","",F10-E10) -> 0 | H10: =IFERROR(E10/F10,"na") -> na | I10: =IFERROR(G10/F10,"na") -> na | J10: =IF(E10="","",J$5) -> 38 | K10: =IF(F10="","",K$5) -> 300 | L10: =IF(G10="","",L$5) -> 262 | M10: =IF($D10="","",'Total & Budget Targets'!$G$44) -> 0 | N10: =IF($D10="","",'Total & Budget Targets'!$G$63) -> 0 | O10: =IF($D10="","",'Total & Budget Targets'!$G$69) -> 0
A11: =A10+1 -> 7 | C11: =IF(D10="","",IF(D10+1>'Date Info'!$D$21,"",D10+1)) -> 45870 | D11: =IFERROR(IF(C11="","",IF(EOMONTH(C11,0)>'Date Info'!$D$21,'Date Info'!$D$21,EOMONTH(C11,0))),"") -> 45900 | E11: =IF($D11="","",IFERROR(SUMIFS(Expenses!$E:$E,Expenses!$B:$B,">="&$C11,Expenses!$B:$B,"<="&$D11),"na")) -> 0 | F11: =IF($D11="","",IFERROR(SUMIFS(Income!$D:$D,Income!$B:$B,">="&$C11,Income!$B:$B,"<="&$D11),"na")) -> 0 | G11: =IF(E11="","",F11-E11) -> 0 | H11: =IFERROR(E11/F11,"na") -> na | I11: =IFERROR(G11/F11,"na") -> na | J11: =IF(E11="","",J$5) -> 38 | K11: =IF(F11="","",K$5) -> 300 | L11: =IF(G11="","",L$5) -> 262 | M11: =IF($D11="","",'Total & Budget Targets'!$G$44) -> 0 | N11: =IF($D11="","",'Total & Budget Targets'!$G$63) -> 0 | O11: =IF($D11="","",'Total & Budget Targets'!$G$69) -> 0
A12: =A11+1 -> 8 | C12: =IF(D11="","",IF(D11+1>'Date Info'!$D$21,"",D11+1)) -> 45901 | D12: =IFERROR(IF(C12="","",IF(EOMONTH(C12,0)>'Date Info'!$D$21,'Date Info'!$D$21,EOMONTH(C12,0))),"") -> 45930 | E12: =IF($D12="","",IFERROR(SUMIFS(Expenses!$E:$E,Expenses!$B:$B,">="&$C12,Expenses!$B:$B,"<="&$D12),"na")) -> 0 | F12: =IF($D12="","",IFERROR(SUMIFS(Income!$D:$D,Income!$B:$B,">="&$C12,Income!$B:$B,"<="&$D12),"na")) -> 0 | G12: =IF(E12="","",F12-E12) -> 0 | H12: =IFERROR(E12/F12,"na") -> na | I12: =IFERROR(G12/F12,"na") -> na | J12: =IF(E12="","",J$5) -> 38 | K12: =IF(F12="","",K$5) -> 300 | L12: =IF(G12="","",L$5) -> 262 | M12: =IF($D12="","",'Total & Budget Targets'!$G$44) -> 0 | N12: =IF($D12="","",'Total & Budget Targets'!$G$63) -> 0 | O12: =IF($D12="","",'Total & Budget Targets'!$G$69) -> 0
A13: =A12+1 -> 9 | C13: =IF(D12="","",IF(D12+1>'Date Info'!$D$21,"",D12+1)) -> 45931 | D13: =IFERROR(IF(C13="","",IF(EOMONTH(C13,0)>'Date Info'!$D$21,'Date Info'!$D$21,EOMONTH(C13,0))),"") -> 45961 | E13: =IF($D13="","",IFERROR(SUMIFS(Expenses!$E:$E,Expenses!$B:$B,">="&$C13,Expenses!$B:$B,"<="&$D13),"na")) -> 0 | F13: =IF($D13="","",IFERROR(SUMIFS(Income!$D:$D,Income!$B:$B,">="&$C13,Income!$B:$B,"<="&$D13),"na")) -> 0 | G13: =IF(E13="","",F13-E13) -> 0 | H13: =IFERROR(E13/F13,"na") -> na | I13: =IFERROR(G13/F13,"na") -> na | J13: =IF(E13="","",J$5) -> 38 | K13: =IF(F13="","",K$5) -> 300 | L13: =IF(G13="","",L$5) -> 262 | M13: =IF($D13="","",'Total & Budget Targets'!$G$44) -> 0 | N13: =IF($D13="","",'Total & Budget Targets'!$G$63) -> 0 | O13: =IF($D13="","",'Total & Budget Targets'!$G$69) -> 0
A14: =A13+1 -> 10 | C14: =IF(D13="","",IF(D13+1>'Date Info'!$D$21,"",D13+1)) -> 45962 | D14: =IFERROR(IF(C14="","",IF(EOMONTH(C14,0)>'Date Info'!$D$21,'Date Info'!$D$21,EOMONTH(C14,0))),"") -> 45991 | E14: =IF($D14="","",IFERROR(SUMIFS(Expenses!$E:$E,Expenses!$B:$B,">="&$C14,Expenses!$B:$B,"<="&$D14),"na")) -> 0 | F14: =IF($D14="","",IFERROR(SUMIFS(Income!$D:$D,Income!$B:$B,">="&$C14,Income!$B:$B,"<="&$D14),"na")) -> 0 | G14: =IF(E14="","",F14-E14) -> 0 | H14: =IFERROR(E14/F14,"na") -> na | I14: =IFERROR(G14/F14,"na") -> na | J14: =IF(E14="","",J$5) -> 38 | K14: =IF(F14="","",K$5) -> 300 | L14: =IF(G14="","",L$5) -> 262 | M14: =IF($D14="","",'Total & Budget Targets'!$G$44) -> 0 | N14: =IF($D14="","",'Total & Budget Targets'!$G$63) -> 0 | O14: =IF($D14="","",'Total & Budget Targets'!$G$69) -> 0
A15: =A14+1 -> 11 | C15: =IF(D14="","",IF(D14+1>'Date Info'!$D$21,"",D14+1)) -> 45992 | D15: =IFERROR(IF(C15="","",IF(EOMONTH(C15,0)>'Date Info'!$D$21,'Date Info'!$D$21,EOMONTH(C15,0))),"") -> 46022 | E15: =IF($D15="","",IFERROR(SUMIFS(Expenses!$E:$E,Expenses!$B:$B,">="&$C15,Expenses!$B:$B,"<="&$D15),"na")) -> 0 | F15: =IF($D15="","",IFERROR(SUMIFS(Income!$D:$D,Income!$B:$B,">="&$C15,Income!$B:$B,"<="&$D15),"na")) -> 0 | G15: =IF(E15="","",F15-E15) -> 0 | H15: =IFERROR(E15/F15,"na") -> na | I15: =IFERROR(G15/F15,"na") -> na | J15: =IF(E15="","",J$5) -> 38 | K15: =IF(F15="","",K$5) -> 300 | L15: =IF(G15="","",L$5) -> 262 | M15: =IF($D15="","",'Total & Budget Targets'!$G$44) -> 0 | N15: =IF($D15="","",'Total & Budget Targets'!$G$63) -> 0 | O15: =IF($D15="","",'Total & Budget Targets'!$G$69) -> 0
A16: =A15+1 -> 12 | C16: =IF(D15="","",IF(D15+1>'Date Info'!$D$21,"",D15+1)) -> 46023 | D16: =IFERROR(IF(C16="","",IF(EOMONTH(C16,0)>'Date Info'!$D$21,'Date Info'!$D$21,EOMONTH(C16,0))),"") -> 46053 | E16: =IF($D16="","",IFERROR(SUMIFS(Expenses!$E:$E,Expenses!$B:$B,">="&$C16,Expenses!$B:$B,"<="&$D16),"na")) -> 0 | F16: =IF($D16="","",IFERROR(SUMIFS(Income!$D:$D,Income!$B:$B,">="&$C16,Income!$B:$B,"<="&$D16),"na")) -> 0 | G16: =IF(E16="","",F16-E16) -> 0 | H16: =IFERROR(E16/F16,"na") -> na | I16: =IFERROR(G16/F16,"na") -> na | J16: =IF(E16="","",J$5) -> 38 | K16: =IF(F16="","",K$5) -> 300 | L16: =IF(G16="","",L$5) -> 262 | M16: =IF($D16="","",'Total & Budget Targets'!$G$44) -> 0 | N16: =IF($D16="","",'Total & Budget Targets'!$G$63) -> 0 | O16: =IF($D16="","",'Total & Budget Targets'!$G$69) -> 0
A17: =A16+1 -> 13 | C17: =IF(D16="","",IF(D16+1>'Date Info'!$D$21,"",D16+1)) -> 46054 | D17: =IFERROR(IF(C17="","",IF(EOMONTH(C17,0)>'Date Info'!$D$21,'Date Info'!$D$21,EOMONTH(C17,0))),"") -> 46081 | E17: =IF($D17="","",IFERROR(SUMIFS(Expenses!$E:$E,Expenses!$B:$B,">="&$C17,Expenses!$B:$B,"<="&$D17),"na")) -> 0 | F17: =IF($D17="","",IFERROR(SUMIFS(Income!$D:$D,Income!$B:$B,">="&$C17,Income!$B:$B,"<="&$D17),"na")) -> 0 | G17: =IF(E17="","",F17-E17) -> 0 | H17: =IFERROR(E17/F17,"na") -> na | I17: =IFERROR(G17/F17,"na") -> na | J17: =IF(E17="","",J$5) -> 38 | K17: =IF(F17="","",K$5) -> 300 | L17: =IF(G17="","",L$5) -> 262 | M17: =IF($D17="","",'Total & Budget Targets'!$G$44) -> 0 | N17: =IF($D17="","",'Total & Budget Targets'!$G$63) -> 0 | O17: =IF($D17="","",'Total & Budget Targets'!$G$69) -> 0
... A404: =A403+1 -> 400 | C404: =IF(D403="","",IF(D403+1>'Date Info'!$D$21,"",D403+1)) -> 57831 | D404: =IFERROR(IF(C404="","",IF(EOMONTH(C404,0)>'Date Info'!$D$21,'Date Info'!$D$21,EOMONTH(C404,0))),"") -> 57861 | E404: =IF($D404="","",IFERROR(SUMIFS(Expenses!$E:$E,Expenses!$B:$B,">="&$C404,Expenses!$B:$B,"<="&$D404),"na")) -> 0 | F404: =IF($D404="","",IFERROR(SUMIFS(Income!$D:$D,Income!$B:$B,">="&$C404,Income!$B:$B,"<="&$D404),"na")) -> 0 | G404: =IF(E404="","",F404-E404) -> 0 | H404: =IFERROR(E404/F404,"na") -> na | I404: =IFERROR(G404/F404,"na") -> na | J404: =IF(E404="","",J$5) -> 38 | K404: =IF(F404="","",K$5) -> 300 | L404: =IF(G404="","",L$5) -> 262 | M404: =IF($D404="","",'Total & Budget Targets'!$G$44) -> 0 | N404: =IF($D404="","",'Total & Budget Targets'!$G$63) -> 0 | O404: =IF($D404="","",'Total & Budget Targets'!$G$69) -> 0

Sheet Category Setup
B2: Expense Categories (up to 40) | D2: Notes (Optional):
A3: 1 | B3: Bills & Utilities | D3: Electricity Bill, Water Bill, Broadband, Mobile Recharge, DTH
A4: 2 | B4: Childcare & Baby Needs | D4: Diapers, Baby Food, Toys, School Stationery
A5: 3 | B5: Commute | D5: Metro, Bus, Auto-rickshaw, Train, Ola/Uber, Fuel for commute
A6: 4 | B6: Education | D6: School Fees, College Tuition, Coaching Classes, Online Courses
A7: 6 | B7: Electronics & Gadgets | D7: Mobile Phones, Laptops, Smartwatches, Earphones
A8: 7 | B8: Entertainment | D8: Movies, Concerts, Video Games, Online Streaming, Events
A9: 8 | B9: Familly | D9: Parents' Allowance, Kids' School Fees, Household Help Salary
A10: 26 | B10: Fitness | D10: Gym Membership, Yoga Classes, Sports Equipment, Protein Powder
A11: 9 | B11: Snacks & Quick Bites | D11: Office tea/coffee, Small breaks, Bakery items, Juice, chips, biscuits
A12: 10 | B12: Fuel | D12: Petrol, Diesel, CNG, Electric Charging Stations
A13: 11 | B13: Gifts | D13: Birthday Gifts, Anniversary Gifts, Festivals, Wedding Gifts
A14: 12 | B14: Groceries | D14: Vegetables, Fruits, Dairy, Meat, Frozen Food, Spices, Staples
... A28: 24 | B28: Fines & Penalties | D28: Traffic Challan, Late Fee, Overweight Ticket, etc
A29: 25 | B29: Other
A30: 28
A31: 29
A32: 30
A33: 31
A34: 32
A35: 33
A36: 34
A37: 35
A38: 36
A39: 37
A40: 38
A41: 39
A42: 40
B44: Income Categories | D44: Notes (Optional):
A45: 1 | B45: Expense Money | D45: This Spending money ( To Track from Salary how taken for Expenses)
A46: 2 | B46: Job / Salary
A47: 3 | B47: Side Income
A48: 4
A49: 5
A50: 6
A51: 7
A52: 8
A53: 9
A54: 10
A55: 11
...

Sheet Date Info
B2: Overall Time Period
B4: Transaction Dates | C4: Expenses | D4: Income | E4: Overall | F4: Month | G4: Year
B5: Oldest | C5: =IFERROR(IF(MIN(Expenses!$B:$B)=0,"na",MIN(Expenses!$B:$B)),"na") -> 45717 | D5: =IFERROR(IF(MIN(Income!$B:$B)=0,"na",MIN(Income!$B:$B)),"na") -> 45717 | E5: =IFERROR(IF(MIN(C5:D5)=0,"na",MIN(C5:D5)),"na") -> 45717 | F5: =IFERROR(MONTH(E5),"na") -> 3 | G5: =IFERROR(YEAR(E5),"na") -> 2025
B6: Newest | C6: =IFERROR(IF(MAX(Expenses!$B:$B)=0,"na",MAX(Expenses!$B:$B)),"na") -> 45717 | D6: =IFERROR(IF(MAX(Income!$B:$B)=0,"na",MAX(Income!$B:$B)),"na") -> 45717 | E6: =IFERROR(IF(MAX(C6:D6)=0,"na",MAX(C6:D6)),"na") -> 45717 | F6: =IFERROR(MONTH(E6),"na") -> 3 | G6: =IFERROR(YEAR(E6),"na") -> 2025
B9: Time Periods
B11: Period | C11: Start Date | D11: End Date | E11: Text
B12: Last month | C12: =IFERROR(DATE(G6,F6,1),"na") -> 45717 | D12: =IFERROR(EOMONTH(C12,0),"na") -> 45747 | E12: =B12&" ("&TEXT(C12,"mmm-yy")&")" -> Last month (Mar-25)
B13: Last 3 months | C13: =IFERROR(DATE(YEAR($C$12),MONTH($C$12)-2,1),"na") -> 45658 | D13: =$D$12 -> 45747 | E13: =B13&" ("&TEXT(C13,"mmm-yy")&" to "&TEXT(D13,"mmm-yy")&")" -> Last 3 months (Jan-25 to Mar-25)
B14: Last 6 months | C14: =IFERROR(DATE(YEAR($C$12),MONTH($C$12)-5,1),"na") -> 45566 | D14: =$D$12 -> 45747 | E14: =B14&" ("&TEXT(C14,"mmm-yy")&" to "&TEXT(D14,"mmm-yy")&")" -> Last 6 months (Oct-24 to Mar-25)
B15: Last 12 months | C15: =IFERROR(DATE(YEAR($C$12),MONTH($C$12)-11,1),"na") -> 45383 | D15: =$D$12 -> 45747 | E15: =B15&" ("&TEXT(C15,"mmm-yy")&" to "&TEXT(D15,"mmm-yy")&")" -> Last 12 months (Apr-24 to Mar-25)
B16: Year to date | C16: =IFERROR(DATE(G6,1,1),"na") -> 45658 | D16: =$D$12 -> 45747 | E16: =B16&" ("&TEXT(C16,"mmm-yy")&" to "&TEXT(D16,"mmm-yy")&")" -> Year to date (Jan-25 to Mar-25)
B17: All | C17: =IFERROR(DATE(G5,F5,1),"na") -> 45717 | D17: =$D$12 -> 45747 | E17: =B17&" ("&TEXT(C17,"mmm-yy")&" to "&TEXT(D17,"mmm-yy")&")" -> All (Mar-25 to Mar-25)
B18: Custom | C18: #REF! | D18: #REF! | E18: Custom
B20: Selected time period | E20: # of months
B21: =DashBoard!C2 -> 0 | C21: =IFERROR(INDEX(C12:C18,MATCH($B$21,$E$12:$E$18,0),0),"") | D21: =IFERROR(INDEX(D12:D18,MATCH($B$21,$E$12:$E$18,0),0),"") | E21: =IFERROR(MAX(((YEAR(D21)-YEAR(C21))*12+MONTH(D21)-MONTH(C21)+1),1),1) -> 1
B23: Selected Time Period label: | C23: =TEXT(E21,"#,##0")&IF(ROUND(E21,0)=1," month"," months") -> 1 month
B25: Total months | C25: =IFERROR(MAX((G6-G5)*12+(F6-F5)+1,1),1) -> 1
B26: All Time Period Label: | C26: =TEXT(C25,"#,##0")&IF(ROUND(C25,0)=1," month"," months") -> 1 month
B39: Historical Comparison Time Periods
C41: Time Period 1 | E41: Time Period 2
B42: Label | C42: Start Date | D42: End Date | E42: Start Date | F42: End Date
B43: Latest month vs. previous month | C43: =IFERROR(DATE(YEAR(D44),MONTH(D44),1),"na") -> 45717 | D43: =IFERROR(EOMONTH(E6,0),"na") -> 45747 | E43: =DATE(YEAR(C43),MONTH(C43)-1,DAY(C43)) -> 45689 | F43: =EOMONTH(E43,0) -> 45716
B44: Latest month vs. last year | C44: =IFERROR(DATE(YEAR(D44),MONTH(D44),1),"na") -> 45717 | D44: =$D$43 -> 45747 | E44: =DATE(YEAR(C44)-1,MONTH(C44),DAY(C44)) -> 45352 | F44: =DATE(YEAR(D44)-1,MONTH(D44),DAY(D44)) -> 45382
B45: Past 3 months vs. last year | C45: =IFERROR(DATE(YEAR(D45),MONTH(D45)-2,1),"na") -> 45658 | D45: =$D$43 -> 45747 | E45: =DATE(YEAR(C45)-1,MONTH(C45),DAY(C45)) -> 45292 | F45: =DATE(YEAR(D45)-1,MONTH(D45),DAY(D45)) -> 45382
B46: Past 6 months vs. last year | C46: =IFERROR(DATE(YEAR(D46),MONTH(D46)-5,1),"na") -> 45566 | D46: =$D$43 -> 45747 | E46: =DATE(YEAR(C46)-1,MONTH(C46),DAY(C46)) -> 45200 | F46: =DATE(YEAR(D46)-1,MONTH(D46),DAY(D46)) -> 45382
B47: Past 12 months vs. last year | C47: =IFERROR(DATE(YEAR(D47),MONTH(D47)-11,1),"na") -> 45383 | D47: =$D$43 -> 45747 | E47: =DATE(YEAR(C47)-1,MONTH(C47),DAY(C47)) -> 45017 | F47: =DATE(YEAR(D47)-1,MONTH(D47),DAY(D47)) -> 45382
B48: Year to date vs. last year | C48: =IFERROR(DATE(YEAR(D48),1,1),"na") -> 45658 | D48: =$D$43 -> 45747 | E48: =DATE(YEAR(C48)-1,MONTH(C48),DAY(C48)) -> 45292 | F48: =DATE(YEAR(D48)-1,MONTH(D48),DAY(D48)) -> 45382
B49: Custom | C49: ='[1]Historical Comparison'!J3 -> #REF! | D49: ='[1]Historical Comparison'!J4 -> #REF! | E49: ='[1]Historical Comparison'!K3 -> #REF! | F49: ='[1]Historical Comparison'!K4 -> #REF!
A51: ='[1]Historical Comparison'!C2 -> #REF! | B51: Selected time period
A52: =MATCH($A$51,$B$43:$B$49,0) -> #REF! | B52: =OFFSET(B$42,$A52,0) -> #REF! | C52: =IFERROR(IF($A$52<7,DATE(YEAR(OFFSET(C$42,$A52,0)),MONTH(OFFSET(C$42,$A52,0)),1),OFFSET(C$42,$A52,0)),"na") -> na | D52: =IFERROR(IF($A$52<7,EOMONTH(OFFSET(D$42,$A52,0),0),OFFSET(D$42,$A52,0)),"na") -> na | E52: =IFERROR(IF($A$52<7,DATE(YEAR(OFFSET(E$42,$A52,0)),MONTH(OFFSET(E$42,$A52,0)),1),OFFSET(E$42,$A52,0)),"na") -> na | F52: =IFERROR(IF($A$52<7,EOMONTH(OFFSET(F$42,$A52,0),0),OFFSET(F$42,$A52,0)),"na") -> na
B55: Implied # of months | D55: =IFERROR(MAX(ROUND((D52-C52+1)/(365/12),1),0),0) -> 0 | F55: =IFERROR(MAX(ROUND((F52-E52+1)/(365/12),1),0),0) -> 0
B56: Label: | D56: =IF(D55=1,TEXT(C52,"mmmm-yyyy"),TEXT(C52,"mmm-yyyy")&" to "&TEXT(D52,"mmm-yyyy")) -> na to na | F56: =IF(F55=1,TEXT(E52,"mmmm-yyyy"),TEXT(E52,"mmm-yyyy")&" to "&TEXT(F52,"mmm-yyyy")) -> na to na
B57: # of months label: | D57: =IF(D55=1,"(1 month)","("&TEXT(D55,"0")&" months)") -> (0 months) | F57: =IF(F55=1,"(1 month)","("&TEXT(F55,"0")&" months)") -> (0 months)
B63: PortFolio Tracking Sheet details
